Workbook
Name SegmentaciónDeDatos_Años__Fecha: #N/A
Name SegmentaciónDeDatos_Ciudad: #N/A
Name SegmentaciónDeDatos_Meses__Fecha: #N/A
Name SegmentaciónDeDatos_Nivel_Venta: #N/A
Name SegmentaciónDeDatos_Producto: #N/A
Name SegmentaciónDeDatos_Producto1: #N/A
Name SegmentaciónDeDatos_Territorio: #N/A
Name SegmentaciónDeDatos_Vendedor: #N/A
Name SegmentaciónDeDatos_Vendedor1: #N/A

Sheet Datos_Peru
A1: Lugar | B1: Cliente | C1: Vendedor | D1: Territorio | E1: Fecha | F1: Socio | G1: Ventas | H1: Cantidad | I1: Producto | J1: Precio_Unitario | K1: Nivel_Venta
A2: Huancayo, Peru | B2: CORPORACION GRAFICA NAVARRETE | C2: José | D2: Sur | E2: 42490.458 | F2: Ringo | G2: 173330 | H2: 24 | I2: Accesorios | J2: =+Table2[[#This Row],[Ventas]]/Table2[[#This Row],[Cantidad]] -> 7222.0833 | K2: =+_xlfn.IFS(Table2[[#This Row],[Ventas]]>200000,"Alta", Table2[[#This Row],[Ventas]]>100000,"Media",TRUE,"Bajo") -> Media | M2: Territorio | N2: Total_vendido | O2: Promedio/Territorio
A3: Arequipa, Peru | B3: San Martin Inc | C3: Víctor | D3: Norte | E3: 42482.458 | F3: Ringo | G3: 235562 | H3: 16 | I3: Viajes | J3: =+Table2[[#This Row],[Ventas]]/Table2[[#This Row],[Cantidad]] -> 14722.625 | K3: =+_xlfn.IFS(Table2[[#This Row],[Ventas]]>200000,"Alta", Table2[[#This Row],[Ventas]]>100000,"Media",TRUE,"Bajo") -> Alta | M3: Norte | N3: =+SUMIFS(G:G,D:D,"Norte") -> 61386576 | O3: =AVERAGEIFS(G:G,D:D,"Norte") -> 149359.07
A4: Arequipa, Peru | B4: Unique, S.A. | C4: Víctor | D4: Norte | E4: 42482.458 | F4: Ringo | G4: 98041 | H4: 33 | I4: Viajes | J4: =+Table2[[#This Row],[Ventas]]/Table2[[#This Row],[Cantidad]] -> 2970.9394 | K4: =+_xlfn.IFS(Table2[[#This Row],[Ventas]]>200000,"Alta", Table2[[#This Row],[Ventas]]>100000,"Media",TRUE,"Bajo") -> Bajo | M4: Sur | N4: =+SUMIFS(G:G,D:D,"Sur") -> 85178402 | O4: =AVERAGEIFS(G:G,D:D,"Sur") -> 151293.79
A5: Arequipa, Peru | B5: Banco Interno | C5: Víctor | D5: Norte | E5: 42481.458 | F5: Ringo | G5: 112955 | H5: 30 | I5: Viajes | J5: =+Table2[[#This Row],[Ventas]]/Table2[[#This Row],[Cantidad]] -> 3765.1667 | K5: =+_xlfn.IFS(Table2[[#This Row],[Ventas]]>200000,"Alta", Table2[[#This Row],[Ventas]]>100000,"Media",TRUE,"Bajo") -> Media
A6: Cusco, Peru | B6: Américana de Contactos | C6: Víctor | D6: Norte | E6: 42489.458 | F6: John | G6: 183858 | H6: 31 | I6: Juguetes | J6: =+Table2[[#This Row],[Ventas]]/Table2[[#This Row],[Cantidad]] -> 5930.9032 | K6: =+_xlfn.IFS(Table2[[#This Row],[Ventas]]>200000,"Alta", Table2[[#This Row],[Ventas]]>100000,"Media",TRUE,"Bajo") -> Media | M6: Socio | N6: Total_vendido
A7: Cajamarca, Peru | B7: Gloria | C7: Víctor | D7: Norte | E7: 42482.458 | F7: Ringo | G7: 232459 | H7: 29 | I7: Viajes | J7: =+Table2[[#This Row],[Ventas]]/Table2[[#This Row],[Cantidad]] -> 8015.8276 | K7: =+_xlfn.IFS(Table2[[#This Row],[Ventas]]>200000,"Alta", Table2[[#This Row],[Ventas]]>100000,"Media",TRUE,"Bajo") -> Alta | M7: George | N7: =+SUMIFS(G:G,F:F,"George") -> 6096061
A8: Piura, Peru | B8: CORPORACION GRAFICA NAVARRETE | C8: José | D8: Sur | E8: 42490.458 | F8: Ringo | G8: 249370 | H8: 27 | I8: Juguetes | J8: =+Table2[[#This Row],[Ventas]]/Table2[[#This Row],[Cantidad]] -> 9235.9259 | K8: =+_xlfn.IFS(Table2[[#This Row],[Ventas]]>200000,"Alta", Table2[[#This Row],[Ventas]]>100000,"Media",TRUE,"Bajo") -> Alta | M8: John | N8: =+SUMIFS(G:G,F:F,"John") -> 32706823
A9: Piura, Peru | B9: Profuturo AFP | C9: Víctor | D9: Norte | E9: 42473.458 | F9: Ringo | G9: 149041 | H9: 24 | I9: Viajes | J9: =+Table2[[#This Row],[Ventas]]/Table2[[#This Row],[Cantidad]] -> 6210.0417 | K9: =+_xlfn.IFS(Table2[[#This Row],[Ventas]]>200000,"Alta", Table2[[#This Row],[Ventas]]>100000,"Media",TRUE,"Bajo") -> Media | M9: Paul | N9: =+SUMIFS(G:G,F:F,"Paul") -> 13129951
A10: Lima, Peru | B10: Seguros Internos SAC | C10: Edwin | D10: Norte | E10: 42242.458 | F10: John | G10: 186253 | H10: 17 | I10: Accesorios | J10: =+Table2[[#This Row],[Ventas]]/Table2[[#This Row],[Cantidad]] -> 10956.059 | K10: =+_xlfn.IFS(Table2[[#This Row],[Ventas]]>200000,"Alta", Table2[[#This Row],[Ventas]]>100000,"Media",TRUE,"Bajo") -> Media | M10: Ringo | N10: =+SUMIFS(G:G,F:F,"Ringo") -> 94632143
A11: Lima, Peru | B11: Servicios Generales | C11: Víctor | D11: Norte | E11: 42247.458 | F11: John | G11: 154709 | H11: 37 | I11: Calzado | J11: =+Table2[[#This Row],[Ventas]]/Table2[[#This Row],[Cantidad]] -> 4181.3243 | K11: =+_xlfn.IFS(Table2[[#This Row],[Ventas]]>200000,"Alta", Table2[[#This Row],[Ventas]]>100000,"Media",TRUE,"Bajo") -> Media
A12: Trujillo, Peru | B12: IFH Peru LTD | C12: Edwin | D12: Norte | E12: 42230.458 | F12: Ringo | G12: 198586 | H12: 28 | I12: Accesorios | J12: =+Table2[[#This Row],[Ventas]]/Table2[[#This Row],[Cantidad]] -> 7092.3571 | K12: =+_xlfn.IFS(Table2[[#This Row],[Ventas]]>200000,"Alta", Table2[[#This Row],[Ventas]]>100000,"Media",TRUE,"Bajo") -> Media | M12: Vendedor | N12: Operaciones/vendedor | O12: Total_vendido
A13: Trujillo, Peru | B13: BOTICAS & SALUD S.A.C. | C13: Nadia | D13: Sur | E13: 42235.458 | F13: Ringo | G13: 100738 | H13: 15 | I13: Electrodomésticos | J13: =+Table2[[#This Row],[Ventas]]/Table2[[#This Row],[Cantidad]] -> 6715.8667 | K13: =+_xlfn.IFS(Table2[[#This Row],[Ventas]]>200000,"Alta", Table2[[#This Row],[Ventas]]>100000,"Media",TRUE,"Bajo") -> Media | M13: Jose | N13: =+COUNTIFS(Datos_Peru!C:C,"José") -> 93 | O13: =+SUMIFS(Datos_Peru!G:G,Datos_Peru!C:C,"José") -> 13535221
A14: Trujillo, Peru | B14: Supermercados Peruanos S.A. | C14: Víctor | D14: Norte | E14: 42247.458 | F14: John | G14: 157832 | H14: 40 | I14: Juguetes | J14: =+Table2[[#This Row],[Ventas]]/Table2[[#This Row],[Cantidad]] -> 3945.8 | K14: =+_xlfn.IFS(Table2[[#This Row],[Ventas]]>200000,"Alta", Table2[[#This Row],[Ventas]]>100000,"Media",TRUE,"Bajo") -> Media | M14: Victor | N14: =+COUNTIFS(Datos_Peru!C:C,"Víctor") -> 254 | O14: =+SUMIFS(Datos_Peru!G:G,Datos_Peru!C:C,"Víctor") -> 38761317
A15: Trujillo, Peru | B15: Supermercados Peruanos S.A. | C15: Víctor | D15: Norte | E15: 42247.458 | F15: John | G15: 244028 | H15: 24 | I15: Accesorios | J15: =+Table2[[#This Row],[Ventas]]/Table2[[#This Row],[Cantidad]] -> 10167.833 | K15: =+_xlfn.IFS(Table2[[#This Row],[Ventas]]>200000,"Alta", Table2[[#This Row],[Ventas]]>100000,"Media",TRUE,"Bajo") -> Alta | M15: Edwin | N15: =+COUNTIFS(Datos_Peru!C:C,"Edwin") -> 93 | O15: =+SUMIFS(Datos_Peru!G:G,Datos_Peru!C:C,"Edwin") -> 13149429
A16: Huancayo, Peru | B16: San Martin Inc | C16: Marco | D16: Sur | E16: 42244.458 | F16: Ringo | G16: 164158 | H16: 28 | I16: Electrodomésticos | J16: =+Table2[[#This Row],[Ventas]]/Table2[[#This Row],[Cantidad]] -> 5862.7857 | K16: =+_xlfn.IFS(Table2[[#This Row],[Ventas]]>200000,"Alta", Table2[[#This Row],[Ventas]]>100000,"Media",TRUE,"Bajo") -> Media | M16: Nadia | N16: =+COUNTIFS(Datos_Peru!C:C,"Nadia") -> 83 | O16: =+SUMIFS(Datos_Peru!G:G,Datos_Peru!C:C,"Nadia") -> 12271934
A17: Huancayo, Peru | B17: IFH Peru LTD | C17: María | D17: Norte | E17: 42247.458 | F17: John | G17: 237486 | H17: 36 | I17: Viajes | J17: =+Table2[[#This Row],[Ventas]]/Table2[[#This Row],[Cantidad]] -> 6596.8333 | K17: =+_xlfn.IFS(Table2[[#This Row],[Ventas]]>200000,"Alta", Table2[[#This Row],[Ventas]]>100000,"Media",TRUE,"Bajo") -> Alta | M17: Marco | N17: =+COUNTIFS(Datos_Peru!C:C,"Marco") -> 93 | O17: =+SUMIFS(Datos_Peru!G:G,Datos_Peru!C:C,"Marco") -> 16129498
A18: Huancayo, Peru | B18: OMNIA SOLUTION S.A. | C18: Edwin | D18: Sur | E18: 42237.458 | F18: Ringo | G18: 236324 | H18: 25 | I18: Viajes | J18: =+Table2[[#This Row],[Ventas]]/Table2[[#This Row],[Cantidad]] -> 9452.96 | K18: =+_xlfn.IFS(Table2[[#This Row],[Ventas]]>200000,"Alta", Table2[[#This Row],[Ventas]]>100000,"Media",TRUE,"Bajo") -> Alta | M18: Maria | N18: =+COUNTIFS(Datos_Peru!C:C,"María") -> 80 | O18: =+SUMIFS(Datos_Peru!G:G,Datos_Peru!C:C,"María") -> 11510967
A19: Loreto, Peru | B19: TEXFINA S.A. | C19: Nadia | D19: Sur | E19: 42247.458 | F19: Ringo | G19: 175071 | H19: 38 | I19: Electrodomésticos | J19: =+Table2[[#This Row],[Ventas]]/Table2[[#This Row],[Cantidad]] -> 4607.1316 | K19: =+_xlfn.IFS(Table2[[#This Row],[Ventas]]>200000,"Alta", Table2[[#This Row],[Ventas]]>100000,"Media",TRUE,"Bajo") -> Media | M19: Rosa | N19: =+COUNTIFS(Datos_Peru!C:C,"Rosa") -> 80 | O19: =+SUMIFS(Datos_Peru!G:G,Datos_Peru!C:C,"Rosa") -> 11857489
A20: Loreto, Peru | B20: IFH Peru LTD | C20: Víctor | D20: Norte | E20: 42230.458 | F20: Ringo | G20: 145417 | H20: 22 | I20: Accesorios | J20: =+Table2[[#This Row],[Ventas]]/Table2[[#This Row],[Cantidad]] -> 6609.8636 | K20: =+_xlfn.IFS(Table2[[#This Row],[Ventas]]>200000,"Alta", Table2[[#This Row],[Ventas]]>100000,"Media",TRUE,"Bajo") -> Media | M20: Javier | N20: =+COUNTIFS(Datos_Peru!C:C,"Javier") -> 26 | O20: =+SUMIFS(Datos_Peru!G:G,Datos_Peru!C:C,"Javier") -> 3838966
A21: Loreto, Peru | B21: IFH Peru LTD | C21: Edwin | D21: Norte | E21: 42230.458 | F21: Ringo | G21: 164588 | H21: 41 | I21: Electrodomésticos | J21: =+Table2[[#This Row],[Ventas]]/Table2[[#This Row],[Cantidad]] -> 4014.3415 | K21: =+_xlfn.IFS(Table2[[#This Row],[Ventas]]>200000,"Alta", Table2[[#This Row],[Ventas]]>100000,"Media",TRUE,"Bajo") -> Media | M21: Nora | N21: =+COUNTIFS(Datos_Peru!C:C,"Nora") -> 172 | O21: =+SUMIFS(Datos_Peru!G:G,Datos_Peru!C:C,"Nora") -> 25510157
A22: Loreto, Peru | B22: NEXTEL PERU S.A. | C22: Víctor | D22: Norte | E22: 42229.458 | F22: Ringo | G22: 197823 | H22: 28 | I22: Viajes | J22: =+Table2[[#This Row],[Ventas]]/Table2[[#This Row],[Cantidad]] -> 7065.1071 | K22: =+_xlfn.IFS(Table2[[#This Row],[Ventas]]>200000,"Alta", Table2[[#This Row],[Ventas]]>100000,"Media",TRUE,"Bajo") -> Media
A23: Loreto, Peru | B23: SANDOVAL S.A. - DINET | C23: Rosa | D23: Sur | E23: 42243.458 | F23: Ringo | G23: 164603 | H23: 35 | I23: Electrodomésticos | J23: =+Table2[[#This Row],[Ventas]]/Table2[[#This Row],[Cantidad]] -> 4702.9429 | K23: =+_xlfn.IFS(Table2[[#This Row],[Ventas]]>200000,"Alta", Table2[[#This Row],[Ventas]]>100000,"Media",TRUE,"Bajo") -> Media
A24: Loreto, Peru | B24: MOLINOS & CIA S.A. | C24: Marco | D24: Sur | E24: 42244.458 | F24: Ringo | G24: 62393 | H24: 38 | I24: Electrodomésticos | J24: =+Table2[[#This Row],[Ventas]]/Table2[[#This Row],[Cantidad]] -> 1641.9211 | K24: =+_xlfn.IFS(Table2[[#This Row],[Ventas]]>200000,"Alta", Table2[[#This Row],[Ventas]]>100000,"Media",TRUE,"Bajo") -> Bajo | M24: Producto | N24: Operaciones/Producto | O24: Total_Vendido | P24: Promedio/Producto
A25: Loreto, Peru | B25: Banco Inca | C25: Edwin | D25: Norte | E25: 42230.458 | F25: Ringo | G25: 236606 | H25: 36 | I25: Viajes | J25: =+Table2[[#This Row],[Ventas]]/Table2[[#This Row],[Cantidad]] -> 6572.3889 | K25: =+_xlfn.IFS(Table2[[#This Row],[Ventas]]>200000,"Alta", Table2[[#This Row],[Ventas]]>100000,"Media",TRUE,"Bajo") -> Alta | M25: Accesorios | N25: =+COUNTIFS(I:I,"Accesorios") -> 370 | O25: =+SUMIFS(G:G,I:I,"Accesorios") -> 55047421 | P25: =+AVERAGEIFS(G:G,I:I,"Accesorios") -> 148776.81
A26: Loreto, Peru | B26: Compañía Minera Poderosa, S.A. | C26: Víctor | D26: Norte | E26: 42247.458 | F26: Ringo | G26: 141965 | H26: 24 | I26: Viajes | J26: =+Table2[[#This Row],[Ventas]]/Table2[[#This Row],[Cantidad]] -> 5915.2083 | K26: =+_xlfn.IFS(Table2[[#This Row],[Ventas]]>200000,"Alta", Table2[[#This Row],[Ventas]]>100000,"Media",TRUE,"Bajo") -> Media | M26: Viajes | N26: =+COUNTIFS(I:I,"Viajes") -> 75 | O26: =+SUMIFS(G:G,I:I,"Viajes") -> 12129272 | P26: =+AVERAGEIFS(G:G,I:I,"Viajes") -> 161723.63
A27: Loreto, Peru | B27: CLINICA INTERNACIONAL S.A. | C27: Víctor | D27: Norte | E27: 42247.458 | F27: John | G27: 79057 | H27: 32 | I27: Calzado | J27: =+Table2[[#This Row],[Ventas]]/Table2[[#This Row],[Cantidad]] -> 2470.5312 | K27: =+_xlfn.IFS(Table2[[#This Row],[Ventas]]>200000,"Alta", Table2[[#This Row],[Ventas]]>100000,"Media",TRUE,"Bajo") -> Bajo | M27: Juguetes | N27: =+COUNTIFS(I:I,"Juguetes") -> 244 | O27: =+SUMIFS(G:G,I:I,"Juguetes") -> 37398809 | P27: =+AVERAGEIFS(G:G,I:I,"Juguetes") -> 153273.81
A28: Loreto, Peru | B28: Banco Interno | C28: Nora | D28: Sur | E28: 42236.458 | F28: Ringo | G28: 169756 | H28: 38 | I28: Juguetes | J28: =+Table2[[#This Row],[Ventas]]/Table2[[#This Row],[Cantidad]] -> 4467.2632 | K28: =+_xlfn.IFS(Table2[[#This Row],[Ventas]]>200000,"Alta", Table2[[#This Row],[Ventas]]>100000,"Media",TRUE,"Bajo") -> Media | M28: Calzado | N28: =+COUNTIFS(I:I,"Calzado") -> 85 | O28: =+SUMIFS(G:G,I:I,"Calzado") -> 11862587 | P28: =+AVERAGEIFS(G:G,I:I,"Calzado") -> 139559.85
A29: Loreto, Peru | B29: IFH Peru LTD | C29: María | D29: Norte | E29: 42230.458 | F29: Ringo | G29: 136293 | H29: 27 | I29: Accesorios | J29: =+Table2[[#This Row],[Ventas]]/Table2[[#This Row],[Cantidad]] -> 5047.8889 | K29: =+_xlfn.IFS(Table2[[#This Row],[Ventas]]>200000,"Alta", Table2[[#This Row],[Ventas]]>100000,"Media",TRUE,"Bajo") -> Media | M29: Electrodomestico | N29: =+COUNTIFS(I:I,"Electrodomésticos") -> 200 | O29: =+SUMIFS(G:G,I:I,"Electrodomésticos") -> 30126889 | P29: =+AVERAGEIFS(G:G,I:I,"Electrodomésticos") -> 150634.45
A30: Loreto, Peru | B30: MOLINOS & CIA S.A. | C30: Marco | D30: Sur | E30: 42244.458 | F30: Ringo | G30: 161296 | H30: 23 | I30: Electrodomésticos | J30: =+Table2[[#This Row],[Ventas]]/Table2[[#This Row],[Cantidad]] -> 7012.8696 | K30: =+_xlfn.IFS(Table2[[#This Row],[Ventas]]>200000,"Alta", Table2[[#This Row],[Ventas]]>100000,"Media",TRUE,"Bajo") -> Media
A31: Loreto, Peru | B31: Seguros Internos SAC | C31: Víctor | D31: Norte | E31: 42247.458 | F31: John | G31: 137877 | H31: 22 | I31: Juguetes | J31: =+Table2[[#This Row],[Ventas]]/Table2[[#This Row],[Cantidad]] -> 6267.1364 | K31: =+_xlfn.IFS(Table2[[#This Row],[Ventas]]>200000,"Alta", Table2[[#This Row],[Ventas]]>100000,"Media",TRUE,"Bajo") -> Media
A32: Loreto, Peru | B32: IFH Peru LTD | C32: María | D32: Norte | E32: 42230.458 | F32: Ringo | G32: 71518 | H32: 39 | I32: Electrodomésticos | J32: =+Table2[[#This Row],[Ventas]]/Table2[[#This Row],[Cantidad]] -> 1833.7949 | K32: =+_xlfn.IFS(Table2[[#This Row],[Ventas]]>200000,"Alta", Table2[[#This Row],[Ventas]]>100000,"Media",TRUE,"Bajo") -> Bajo
A33: Loreto, Peru | B33: IFH Peru LTD | C33: María | D33: Norte | E33: 42230.458 | F33: Ringo | G33: 106536 | H33: 15 | I33: Electrodomésticos | J33: =+Table2[[#This Row],[Ventas]]/Table2[[#This Row],[Cantidad]] -> 7102.4 | K33: =+_xlfn.IFS(Table2[[#This Row],[Ventas]]>200000,"Alta", Table2[[#This Row],[Ventas]]>100000,"Media",TRUE,"Bajo") -> Media
A34: Loreto, Peru | B34: SIERRA MACHINES S.A.C. | C34: Marco | D34: Sur | E34: 42247.458 | F34: Ringo | G34: 120304 | H34: 29 | I34: Accesorios | J34: =+Table2[[#This Row],[Ventas]]/Table2[[#This Row],[Cantidad]] -> 4148.4138 | K34: =+_xlfn.IFS(Table2[[#This Row],[Ventas]]>200000,"Alta", Table2[[#This Row],[Ventas]]>100000,"Media",TRUE,"Bajo") -> Media
A35: Loreto, Peru | B35: IFH Peru LTD | C35: María | D35: Norte | E35: 42230.458 | F35: Ringo | G35: 105978 | H35: 22 | I35: Electrodomésticos | J35: =+Table2[[#This Row],[Ventas]]/Table2[[#This Row],[Cantidad]] -> 4817.1818 | K35: =+_xlfn.IFS(Table2[[#This Row],[Ventas]]>200000,"Alta", Table2[[#This Row],[Ventas]]>100000,"Media",TRUE,"Bajo") -> Media
A36: Loreto, Peru | B36: IFH Peru LTD | C36: Edwin | D36: Norte | E36: 42230.458 | F36: Ringo | G36: 216366 | H36: 29 | I36: Electrodomésticos | J36: =+Table2[[#This Row],[Ventas]]/Table2[[#This Row],[Cantidad]] -> 7460.8966 | K36: =+_xlfn.IFS(Table2[[#This Row],[Ventas]]>200000,"Alta", Table2[[#This Row],[Ventas]]>100000,"Media",TRUE,"Bajo") -> Alta
A37: Loreto, Peru | B37: Periódicos Nuevos | C37: Nora | D37: Sur | E37: 42244.458 | F37: John | G37: 124995 | H37: 32 | I37: Viajes | J37: =+Table2[[#This Row],[Ventas]]/Table2[[#This Row],[Cantidad]] -> 3906.0938 | K37: =+_xlfn.IFS(Table2[[#This Row],[Ventas]]>200000,"Alta", Table2[[#This Row],[Ventas]]>100000,"Media",TRUE,"Bajo") -> Media
A38: Loreto, Peru | B38: IFH Peru LTD | C38: María | D38: Norte | E38: 42230.458 | F38: Ringo | G38: 217511 | H38: 28 | I38: Accesorios | J38: =+Table2[[#This Row],[Ventas]]/Table2[[#This Row],[Cantidad]] -> 7768.25 | K38: =+_xlfn.IFS(Table2[[#This Row],[Ventas]]>200000,"Alta", Table2[[#This Row],[Ventas]]>100000,"Media",TRUE,"Bajo") -> Alta
A39: Arequipa, Peru | B39: Supermercados Peruanos S.A. | C39: Víctor | D39: Norte | E39: 42247.458 | F39: John | G39: 96052 | H39: 42 | I39: Juguetes | J39: =+Table2[[#This Row],[Ventas]]/Table2[[#This Row],[Cantidad]] -> 2286.9524 | K39: =+_xlfn.IFS(Table2[[#This Row],[Ventas]]>200000,"Alta", Table2[[#This Row],[Ventas]]>100000,"Media",TRUE,"Bajo") -> Bajo
A40: Arequipa, Peru | B40: Norsemont Perú, S.A.C. | C40: Marco | D40: Sur | E40: 42236.458 | F40: John | G40: 190081 | H40: 21 | I40: Electrodomésticos | J40: =+Table2[[#This Row],[Ventas]]/Table2[[#This Row],[Cantidad]] -> 9051.4762 | K40: =+_xlfn.IFS(Table2[[#This Row],[Ventas]]>200000,"Alta", Table2[[#This Row],[Ventas]]>100000,"Media",TRUE,"Bajo") -> Media
...

Sheet Base_limpia
A1: Ciudad | B1: Lugar | C1: Cliente | D1: Vendedor | E1: Territorio | F1: Socio | G1: Ventas | H1: Cantidad | I1: Producto | J1: Fecha | K1: Precio_Unitario | L1: Nivel_Venta
A2: Huancayo | B2: Peru | C2: CORPORACION GRAFICA NAVARRETE | D2: Jose | E2: Sur | F2: Ringo | G2: 173330 | H2: 24 | I2: Accesorios | J2: 42490 | K2: 7222.0833 | L2: Media
A3: Arequipa | B3: Peru | C3: San Martin Inc | D3: Victor | E3: Norte | F3: Ringo | G3: 235562 | H3: 16 | I3: Viajes | J3: 42482 | K3: 14722.625 | L3: Alta
A4: Arequipa | B4: Peru | C4: Unique, S.A. | D4: Victor | E4: Norte | F4: Ringo | G4: 98041 | H4: 33 | I4: Viajes | J4: 42482 | K4: 2970.9394 | L4: Bajo
A5: Arequipa | B5: Peru | C5: Banco Interno | D5: Victor | E5: Norte | F5: Ringo | G5: 112955 | H5: 30 | I5: Viajes | J5: 42481 | K5: 3765.1667 | L5: Media
A6: Cusco | B6: Peru | C6: Americana de Contactos | D6: Victor | E6: Norte | F6: John | G6: 183858 | H6: 31 | I6: Juguetes | J6: 42489 | K6: 5930.9032 | L6: Media
A7: Cajamarca | B7: Peru | C7: Gloria | D7: Victor | E7: Norte | F7: Ringo | G7: 232459 | H7: 29 | I7: Viajes | J7: 42482 | K7: 8015.8276 | L7: Alta
A8: Piura | B8: Peru | C8: CORPORACION GRAFICA NAVARRETE | D8: Jose | E8: Sur | F8: Ringo | G8: 249370 | H8: 27 | I8: Juguetes | J8: 42490 | K8: 9235.9259 | L8: Alta
A9: Piura | B9: Peru | C9: Profuturo AFP | D9: Victor | E9: Norte | F9: Ringo | G9: 149041 | H9: 24 | I9: Viajes | J9: 42473 | K9: 6210.0417 | L9: Media
A10: Lima | B10: Peru | C10: Seguros Internos SAC | D10: Edwin | E10: Norte | F10: John | G10: 186253 | H10: 17 | I10: Accesorios | J10: 42242 | K10: 10956.059 | L10: Media
A11: Lima | B11: Peru | C11: Servicios Generales | D11: Victor | E11: Norte | F11: John | G11: 154709 | H11: 37 | I11: Calzado | J11: 42247 | K11: 4181.3243 | L11: Media
A12: Trujillo | B12: Peru | C12: IFH Peru LTD | D12: Edwin | E12: Norte | F12: Ringo | G12: 198586 | H12: 28 | I12: Accesorios | J12: 42230 | K12: 7092.3571 | L12: Media
A13: Trujillo | B13: Peru | C13: BOTICAS & SALUD S.A.C. | D13: Nadia | E13: Sur | F13: Ringo | G13: 100738 | H13: 15 | I13: Electrodomesticos | J13: 42235 | K13: 6715.8667 | L13: Media
... A975: Piura | B975: Peru | C975: Union de Concreteras S.A. | D975: Marco | E975: Sur | F975: Ringo | G975: 169409 | H975: 41 | I975: Electrodomesticos | J975: 42277 | K975: 4131.9268 | L975: Media

Sheet Analisis_Vendedores
A2: Territorio | B2: (Todas) | F2: “¿Qué vendedor vendió más?”
A4: Etiquetas de fila | B4: Cantidad1 | C4: Precio_Unitario1 | D4: Total_Ventas
A5: Victor | B5: 7141 | C5: 1502230.7 | D5: 0.26446507 | F5: =Datos_Peru!M12 -> Vendedor | G5: =Datos_Peru!N12 -> Operaciones/vendedor | H5: =Datos_Peru!O12 -> Total_vendido
A6: Nora | B6: 4839 | C6: 996452.65 | D6: 0.17405357 | F6: =Datos_Peru!M13 -> Jose | G6: =Datos_Peru!N13 -> 93 | H6: =Datos_Peru!O13 -> 13535221
A7: Marco | B7: 2666 | C7: 610458.9 | D7: 0.11005015 | F7: =Datos_Peru!M14 -> Victor | G7: =Datos_Peru!N14 -> 254 | H7: =Datos_Peru!O14 -> 38761317
A8: Jose | B8: 2598 | C8: 531318.97 | D8: 0.092349627 | F8: =Datos_Peru!M15 -> Edwin | G8: =Datos_Peru!N15 -> 93 | H8: =Datos_Peru!O15 -> 13149429
A9: Edwin | B9: 2570 | C9: 526207.93 | D9: 0.089717402 | F9: =Datos_Peru!M16 -> Nadia | G9: =Datos_Peru!N16 -> 83 | H9: =Datos_Peru!O16 -> 12271934
A10: Nadia | B10: 2377 | C10: 463782.23 | D10: 0.08373033 | F10: =Datos_Peru!M17 -> Marco | G10: =Datos_Peru!N17 -> 93 | H10: =Datos_Peru!O17 -> 16129498
A11: Rosa | B11: 2401 | C11: 432896.77 | D11: 0.080902608 | F11: =Datos_Peru!M18 -> Maria | G11: =Datos_Peru!N18 -> 80 | H11: =Datos_Peru!O18 -> 11510967
A12: Maria | B12: 2162 | C12: 462454.86 | D12: 0.078538319 | F12: =Datos_Peru!M19 -> Rosa | G12: =Datos_Peru!N19 -> 80 | H12: =Datos_Peru!O19 -> 11857489
A13: Javier | B13: 752 | C13: 146369.24 | D13: 0.026192929 | F13: =Datos_Peru!M20 -> Javier | G13: =Datos_Peru!N20 -> 26 | H13: =Datos_Peru!O20 -> 3838966
A14: Total general | B14: 27506 | C14: 5672172.2 | D14: 1 | F14: =Datos_Peru!M21 -> Nora | G14: =Datos_Peru!N21 -> 172 | H14: =Datos_Peru!O21 -> 25510157
F17: el vendedor que genero mayor ganancia fue Victor con una con un total vendido mayor a 30M que en porcentaje total equivale a un 26,45% a comparacion de sus compareños y otro vendedor que tuvo buen rendimiento fue nora con ventas mayores a 25M con porcentaje de 17.41% total de ventas
F23: con respecto a terroritorios el vendedor victor tuvo un porcentaje de ventas de 63,14% con 7,141 undiade vendidas en el norte, y maria con 18,75% muy por debajo a victor
F26: Y en el territorio sur Nora con un 29.95% de venta con una cantidad vendida de 4,839 unidades, y marcos con 18.94%, jose con 15.89 y nadia 14,41%, rosa 13,92%, donde la region sur domina por estabilidad y sus vendedores son buenos

Sheet Analisis_Producto
A2: Vendedor | B2: (Todas)
F3: “¿Qué producto genera más ventas?”
A4: Etiquetas de fila | B4: Precio_Unitario1 | C4: Cantidad1 | D4: Total_Ventas
A5: 2015 | F5: Producto | G5: Operaciones/Producto | H5: Total_Vendido | I5: Promedio/Producto
A6: jul | F6: Accesorios | G6: 370 | H6: 55047421 | I6: 148776.81
A7: Accesorios | B7: 533718.05 | C7: 2582 | D7: 0.09437713 | F7: Viajes | G7: 75 | H7: 12129272 | I7: 161723.63
A8: Calzado | B8: 71244.791 | C8: 419 | D8: 0.013806136 | F8: Juguetes | G8: 244 | H8: 37398809 | I8: 153273.81
A9: Electrodomesticos | B9: 297947.55 | C9: 1268 | D9: 0.049943787 | F9: Calzado | G9: 85 | H9: 11862587 | I9: 139559.85
A10: Juguetes | B10: 322826.64 | C10: 1652 | D10: 0.059762708 | F10: Electrodomestico | G10: 200 | H10: 30126889 | I10: 150634.45
A11: Viajes | B11: 80612.969 | C11: 348 | D11: 0.01571795
A12: Total jul | B12: 1306350 | C12: 6269 | D12: 0.23360771
A13: ago | F13: De los producto que generan mas ganancias esta en los accesorio con ganancias mayores a 50M, con un promedio de 148,776
A14: Accesorios | B14: 168033.72 | C14: 626 | D14: 0.026288777
A15: Calzado | B15: 31564.682 | C15: 168 | D15: 0.0055250307
A16: Electrodomesticos | B16: 150406.36 | C16: 757 | D16: 0.026661629 | F16: otros producto que mantienen buen rendimiento son los juguetes con ganancias superiores a 30M y otro que tambien aparece los eletrodomesticos con 30M
A17: Juguetes | B17: 92845.897 | C17: 480 | D17: 0.017427055
A18: Viajes | B18: 83725.28 | C18: 372 | D18: 0.015665748
A19: Total ago | B19: 526575.93 | C19: 2403 | D19: 0.091568239 | F19: en cuanto a conteos hay en accesorios 370 pedidos, juguetes 244 y electrodomesticos 200 y el que tuve menos ganacia fue el calzado 85 pedido con ganacia de 11M
A20: sep
A21: Accesorios | B21: 359552.97 | C21: 1563 | D21: 0.058959372
A22: Calzado | B22: 124395.42 | C22: 520 | D22: 0.019965172
A23: Electrodomesticos | B23: 159870.86 | C23: 807 | D23: 0.02957158 | F23: en cuantos en ganancia de producto en el transcurso del año, el 2015 se puede decir que fue el mejor, en cuanto a 2016 se mostro caida cercana a la mitad facturada del 2015
A24: Juguetes | B24: 299638.08 | C24: 1428 | D24: 0.051898039
A25: Viajes | B25: 56502.105 | C25: 260 | D25: 0.0086292784
A26: Total sep | B26: 999959.43 | C26: 4578 | D26: 0.16902344
A27: oct
A28: Accesorios | B28: 93061.356 | C28: 486 | D28: 0.016224012
A29: Calzado | B29: 34531.9 | C29: 191 | D29: 0.0066185866
A30: Electrodomesticos | B30: 122350.35 | C30: 619 | D30: 0.022585184
A31: Juguetes | B31: 97708.509 | C31: 414 | D31: 0.01634864
A32: Viajes | B32: 36130.568 | C32: 86 | D32: 0.0050823328
A33: Total oct | B33: 383782.68 | C33: 1796 | D33: 0.066858755
A34: nov
A35: Accesorios | B35: 94669.594 | C35: 473 | D35: 0.017211451
A36: Calzado | B36: 10136.98 | C36: 91 | D36: 0.0021737662
A37: Electrodomesticos | B37: 23804.407 | C37: 244 | D37: 0.0055216056
A38: Juguetes | B38: 59173.822 | C38: 292 | D38: 0.0094782943
A39: Total nov | B39: 187784.8 | C39: 1100 | D39: 0.034385118
A40: dic
A41: Accesorios | B41: 158137.76 | C41: 706 | D41: 0.026873091
...

Sheet Analisis_Territorio
G2: “¿Dónde se vende más?”
A3: Territorio | B3: Ciudad | C3: Precio_Unitario1 | D3: Total_Ventas
A4: Norte | F4: Territorio | G4: Total_vendido | H4: Promedio/Territorio
B5: Arequipa | C5: 488415.16 | D5: 12713440 | F5: Norte | G5: 61386576 | H5: 149359.07
B6: Cajamarca | C6: 275851.29 | D6: 6854694 | F6: Sur | G6: 85178402 | H6: 151293.79
B7: Cusco | C7: 389764.81 | D7: 9756492
B8: Huancayo | C8: 150102.65 | D8: 3746066 | F8: En territorio el lugar donde mas vende es en la Zona Sur con ganacias de mas de 85M a comparacion de Zona Norte con 61M
B9: Lima | C9: 52260.115 | D9: 1208652
B10: Loreto | C10: 551429.82 | D10: 14246356
B11: Piura | C11: 407538.18 | D11: 10477656
B12: Trujillo | C12: 83975.383 | D12: 2383220 | F12: En la Zona Norte las cuidades donde tuvieron mejor desempezo fueron en Arequipa con 12M, loreto con 14M siendo el mejor con diferencia de 2M y tambien Piura con 10M seguido de cusco con 9M
A13: Total Norte | C13: 2399337.4 | D13: 61386576
A14: Sur
B15: Arequipa | C15: 738779.47 | D15: 19780467
B16: Cajamarca | C16: 384946.31 | D16: 9539582
B17: Cusco | C17: 454504.05 | D17: 11677164 | F17: En la zona Sur Arequipa con 19M y seguido de Loreto casi llegando a los 21M, tambien Piura y cusco en margen del 10M
B18: Huancayo | C18: 241089.44 | D18: 6047917
B19: Lima | C19: 53170.01 | D19: 1550395
B20: Loreto | C20: 803141.66 | D20: 20925598
B21: Piura | C21: 435734.83 | D21: 12062151
B22: Trujillo | C22: 161469.06 | D22: 3595128
A23: Total Sur | C23: 3272834.8 | D23: 85178402
A24: Total general | C24: 5672172.2 | D24: 146564978

Sheet Dash
A3: Etiquetas de fila | B3: Suma de Ventas
A4: Edwin | B4: 13149429
A5: Javier | B5: 3838966
A6: Jose | B6: 13535221
A7: Marco | B7: 16129498
A8: Maria | B8: 11510967
A9: Nadia | B9: 12271934
A10: Nora | B10: 25510157
A11: Rosa | B11: 11857489
A12: Victor | B12: 38761317
A13: Total general | B13: 146564978
A15: Etiquetas de fila | B15: Suma de Ventas
A16: Accesorios | B16: 55047421
A17: Calzado | B17: 11862587
A18: Electrodomesticos | B18: 30126889
A19: Juguetes | B19: 37398809
A20: Viajes | B20: 12129272
A21: Total general | B21: 146564978
A23: Etiquetas de fila | B23: Suma de Ventas
A24: Norte | B24: 61386576
A25: Sur | B25: 85178402
A26: Total general | B26: 146564978
